<?xml version="1.0" ?>
<!--
    This URDF model was generated by transforming the MuJoCo model [2] using the tool [1].
    [1] https://pypi.org/project/mjcf-urdf-simple-converter/
    [2] https://github.com/isri-aist/RoboManipBaselines/tree/master/robo_manip_baselines/envs/assets/mujoco/robots/ur5e
-->
<robot name="mujoco_ur5e">
   <link name="world">
      <inertial>
         <origin xyz="0.0 0.0 0.0" rpy="0.0 0.0 0.0"/>
         <mass value="0.0"/>
         <inertia ixx="0.0" iyy="0.0" izz="0.0" ixy="0" ixz="0" iyz="0"/>
      </inertial>
   </link>
   <link name="ur5e_root_frame">
      <inertial>
         <origin xyz="0.0 0.0 0.0" rpy="0.0 0.0 0.0"/>
         <mass value="0.0"/>
         <inertia ixx="0.0" iyy="0.0" izz="0.0" ixy="0" ixz="0" iyz="0"/>
      </inertial>
   </link>
   <link name="world2ur5e_root_frame_fixed_jointbody">
      <inertial>
         <origin xyz="0.0 0.0 0.0" rpy="0.0 0.0 0.0"/>
         <mass value="0.001"/>
         <inertia ixx="1e-09" iyy="1e-09" izz="1e-09" ixy="0" ixz="0" iyz="0"/>
      </inertial>
   </link>
   <joint type="fixed" name="world2ur5e_root_frame_fixed">
      <parent link="world"/>
      <child link="world2ur5e_root_frame_fixed_jointbody"/>
      <origin xyz="0.0 0.0 0.0" rpy="0.0 0.0 0.0"/>
   </joint>
   <joint type="fixed" name="world2ur5e_root_frame_fixed_offset">
      <parent link="world2ur5e_root_frame_fixed_jointbody"/>
      <child link="ur5e_root_frame"/>
      <origin xyz="-0.0 -0.0 -0.0" rpy="0.0 0.0 0.0"/>
   </joint>
   <link name="base">
      <inertial>
         <origin xyz="0.0 0.0 0.0" rpy="0.0 0.0 0.0"/>
         <mass value="4.0"/>
         <inertia ixx="0.00443333156" iyy="0.00443333156" izz="0.0072" ixy="0" ixz="0" iyz="0"/>
      </inertial>
      <visual name="base_0">
         <origin xyz="6.729613291636444e-07 -3.658243672095132e-07 0.09357351479123255" rpy="-1.47188270226107 -1.5707855306182412 -2.9583795849873327"/>
         <geometry>
            <mesh filename="meshes/converted_base_0.stl"/>
         </geometry>
         <material name="black"/>
      </visual>
      <visual name="base_1">
         <origin xyz="1.5050970612118353e-07 5.029437897684572e-07 0.03113409208382618" rpy="-1.398999536983526 -1.570774933802305 -1.0876125512811239"/>
         <geometry>
            <mesh filename="meshes/converted_base_1.stl"/>
         </geometry>
         <material name="jointgray"/>
      </visual>
   </link>
   <link name="ur5e_root_frame2base_fixed_jointbody">
      <inertial>
         <origin xyz="0.0 0.0 0.0" rpy="0.0 0.0 0.0"/>
         <mass value="0.001"/>
         <inertia ixx="1e-09" iyy="1e-09" izz="1e-09" ixy="0" ixz="0" iyz="0"/>
      </inertial>
   </link>
   <joint type="fixed" name="ur5e_root_frame2base_fixed">
      <parent link="ur5e_root_frame"/>
      <child link="ur5e_root_frame2base_fixed_jointbody"/>
      <origin xyz="0.0 0.0 0.0" rpy="0.0 0.0 0.0"/>
   </joint>
   <joint type="fixed" name="ur5e_root_frame2base_fixed_offset">
      <parent link="ur5e_root_frame2base_fixed_jointbody"/>
      <child link="base"/>
      <origin xyz="-0.0 -0.0 -0.0" rpy="0.0 0.0 0.0"/>
   </joint>
   <link name="shoulder_link">
      <inertial>
         <origin xyz="0.0 0.0 0.0" rpy="0.0 0.0 0.0"/>
         <mass value="3.7"/>
         <inertia ixx="0.0102675" iyy="0.0102675" izz="0.00666" ixy="0" ixz="0" iyz="0"/>
      </inertial>
      <visual name="shoulder_0">
         <origin xyz="0.00015791990090556265 -0.008422927184789035 0.04825544231361248" rpy="2.972049948535049 -1.2403403851965114 -1.5664480416259279"/>
         <geometry>
            <mesh filename="meshes/converted_shoulder_0.stl"/>
         </geometry>
         <material name="urblue"/>
      </visual>
      <visual name="shoulder_1">
         <origin xyz="1.0221602485018881e-06 0.06888462434941042 -0.0005032847963257957" rpy="0.16997294871325141 -1.5622871640585956e-05 1.5708061583761173"/>
         <geometry>
            <mesh filename="meshes/converted_shoulder_1.stl"/>
         </geometry>
         <material name="black"/>
      </visual>
      <visual name="shoulder_2">
         <origin xyz="-4.987111589031359e-05 0.0005636150230643856 -0.01875771788843443" rpy="1.6252845451898668 0.7431999550369857 1.5734657719034488"/>
         <geometry>
            <mesh filename="meshes/converted_shoulder_2.stl"/>
         </geometry>
         <material name="jointgray"/>
      </visual>
   </link>
   <link name="shoulder_pan_joint_jointbody">
      <inertial>
         <origin xyz="0.0 0.0 0.0" rpy="0.0 0.0 0.0"/>
         <mass value="0.001"/>
         <inertia ixx="1e-09" iyy="1e-09" izz="1e-09" ixy="0" ixz="0" iyz="0"/>
      </inertial>
   </link>
   <joint type="revolute" name="shoulder_pan_joint">
      <parent link="base"/>
      <child link="shoulder_pan_joint_jointbody"/>
      <origin xyz="0.0 0.0 0.163" rpy="0.0 0.0 0.0"/>
      <axis xyz="0.0 0.0 1.0"/>
      <limit lower="-6.28319" upper="6.28319" effort="100" velocity="100"/>
   </joint>
   <joint type="fixed" name="shoulder_pan_joint_offset">
      <parent link="shoulder_pan_joint_jointbody"/>
      <child link="shoulder_link"/>
      <origin xyz="-0.0 -0.0 -0.0" rpy="0.0 0.0 0.0"/>
   </joint>
   <link name="upper_arm_link">
      <inertial>
         <origin xyz="0.0 0.0 0.2125" rpy="0.0 0.0 0.0"/>
         <mass value="8.393"/>
         <inertia ixx="0.133886" iyy="0.133886" izz="0.0151074" ixy="0" ixz="0" iyz="0"/>
      </inertial>
      <visual name="upperarm_0">
         <origin xyz="-3.5760646000637493e-06 -0.00019999968769833566 0.21213517773732127" rpy="-0.0003305440898112577 -1.48494256579923e-06 -0.35511939855508967"/>
         <geometry>
            <mesh filename="meshes/converted_upperarm_0.stl"/>
         </geometry>
         <material name="linkgray"/>
      </visual>
      <visual name="upperarm_1">
         <origin xyz="-7.533427155925417e-07 -0.02455902479462408 0.2981274589864789" rpy="0.17716176130958655 7.970340488805405e-05 -0.0004820288661456923"/>
         <geometry>
            <mesh filename="meshes/converted_upperarm_1.stl"/>
         </geometry>
         <material name="black"/>
      </visual>
      <visual name="upperarm_2">
         <origin xyz="1.2475193933552453e-05 -0.020613766259404608 0.21354779136318264" rpy="-4.278980147820466e-05 -0.009396328570252743 1.5726071657176126"/>
         <geometry>
            <mesh filename="meshes/converted_upperarm_2.stl"/>
         </geometry>
         <material name="jointgray"/>
      </visual>
      <visual name="upperarm_3">
         <origin xyz="-1.6738860146607153e-05 0.04530972331282584 0.21224046051237042" rpy="-1.117038519860003e-05 -0.0003347325829139436 1.5712747080499256"/>
         <geometry>
            <mesh filename="meshes/converted_upperarm_3.stl"/>
         </geometry>
         <material name="urblue"/>
      </visual>
   </link>
   <link name="shoulder_lift_joint_jointbody">
      <inertial>
         <origin xyz="0.0 0.0 0.0" rpy="0.0 0.0 0.0"/>
         <mass value="0.001"/>
         <inertia ixx="1e-09" iyy="1e-09" izz="1e-09" ixy="0" ixz="0" iyz="0"/>
      </inertial>
   </link>
   <joint type="revolute" name="shoulder_lift_joint">
      <parent link="shoulder_link"/>
      <child link="shoulder_lift_joint_jointbody"/>
      <origin xyz="0.0 0.138 0.0" rpy="-0.0 1.5707963267948966 0.0"/>
      <axis xyz="0.0 1.0 0.0"/>
      <limit lower="-6.28319" upper="6.28319" effort="100" velocity="100"/>
   </joint>
   <joint type="fixed" name="shoulder_lift_joint_offset">
      <parent link="shoulder_lift_joint_jointbody"/>
      <child link="upper_arm_link"/>
      <origin xyz="-0.0 -0.0 -0.0" rpy="0.0 0.0 0.0"/>
   </joint>
   <link name="forearm_link">
      <inertial>
         <origin xyz="0.0 0.0 0.196" rpy="0.0 0.0 0.0"/>
         <mass value="2.275"/>
         <inertia ixx="0.0311796" iyy="0.0311796" izz="0.004095" ixy="0" ixz="0" iyz="0"/>
      </inertial>
      <visual name="forearm_0">
         <origin xyz="2.6207450606710292e-05 -0.039869278793902285 0.3958893860897068" rpy="0.1489966672854065 0.3108521787989902 1.5710806059285622"/>
         <geometry>
            <mesh filename="meshes/converted_forearm_0.stl"/>
         </geometry>
         <material name="urblue"/>
      </visual>
      <visual name="forearm_1">
         <origin xyz="-2.3636833205504254e-05 -0.0004340911527384576 0.20434307929108567" rpy="0.0003357934988212907 -0.0005516117998196624 1.333297755723175"/>
         <geometry>
            <mesh filename="meshes/converted_forearm_1.stl"/>
         </geometry>
         <material name="linkgray"/>
      </visual>
      <visual name="forearm_2">
         <origin xyz="-9.661516749736769e-06 0.01697650909542407 0.25503902244340926" rpy="-0.1463016154163696 0.0006538606600001717 0.004920260000614754"/>
         <geometry>
            <mesh filename="meshes/converted_forearm_2.stl"/>
         </geometry>
         <material name="black"/>
      </visual>
      <visual name="forearm_3">
         <origin xyz="2.9752030802592747e-06 0.011960668315823576 0.16361682552290555" rpy="2.9784638189700452e-05 0.02032514003029151 1.5715676566435608"/>
         <geometry>
            <mesh filename="meshes/converted_forearm_3.stl"/>
         </geometry>
         <material name="jointgray"/>
      </visual>
   </link>
   <link name="elbow_joint_jointbody">
      <inertial>
         <origin xyz="0.0 0.0 0.0" rpy="0.0 0.0 0.0"/>
         <mass value="0.001"/>
         <inertia ixx="1e-09" iyy="1e-09" izz="1e-09" ixy="0" ixz="0" iyz="0"/>
      </inertial>
   </link>
   <joint type="revolute" name="elbow_joint">
      <parent link="upper_arm_link"/>
      <child link="elbow_joint_jointbody"/>
      <origin xyz="0.0 -0.131 0.425" rpy="0.0 0.0 0.0"/>
      <axis xyz="0.0 1.0 0.0"/>
      <limit lower="-3.1415" upper="3.1415" effort="100" velocity="100"/>
   </joint>
   <joint type="fixed" name="elbow_joint_offset">
      <parent link="elbow_joint_jointbody"/>
      <child link="forearm_link"/>
      <origin xyz="-0.0 -0.0 -0.0" rpy="0.0 0.0 0.0"/>
   </joint>
   <link name="wrist_1_link">
      <inertial>
         <origin xyz="0.0 0.127 0.0" rpy="0.0 0.0 0.0"/>
         <mass value="1.219"/>
         <inertia ixx="0.0025599" iyy="0.0025599" izz="0.0021942" ixy="0" ixz="0" iyz="0"/>
      </inertial>
      <visual name="wrist1_0">
         <origin xyz="-2.324781546803138e-05 0.12628514057599924 0.04897505965681284" rpy="-1.9266664753609 -1.5705837496211885 -0.8138833726102015"/>
         <geometry>
            <mesh filename="meshes/converted_wrist1_0.stl"/>
         </geometry>
         <material name="black"/>
      </visual>
      <visual name="wrist1_1">
         <origin xyz="-3.6644614818292445e-05 0.13040179175860142 -0.039703488660788" rpy="-3.065967817600465 -1.261342943128882 -1.5694033981029945"/>
         <geometry>
            <mesh filename="meshes/converted_wrist1_1.stl"/>
         </geometry>
         <material name="urblue"/>
      </visual>
      <visual name="wrist1_2">
         <origin xyz="-2.0991024420246793e-06 0.11289621782275673 0.01238833387042214" rpy="-3.140097697876837 -1.0305077633093638 -1.5723310737061327"/>
         <geometry>
            <mesh filename="meshes/converted_wrist1_2.stl"/>
         </geometry>
         <material name="jointgray"/>
      </visual>
   </link>
   <link name="wrist_1_joint_jointbody">
      <inertial>
         <origin xyz="0.0 0.0 0.0" rpy="0.0 0.0 0.0"/>
         <mass value="0.001"/>
         <inertia ixx="1e-09" iyy="1e-09" izz="1e-09" ixy="0" ixz="0" iyz="0"/>
      </inertial>
   </link>
   <joint type="revolute" name="wrist_1_joint">
      <parent link="forearm_link"/>
      <child link="wrist_1_joint_jointbody"/>
      <origin xyz="0.0 0.0 0.392" rpy="-0.0 1.5707963267948966 0.0"/>
      <axis xyz="0.0 1.0 0.0"/>
      <limit lower="-6.28319" upper="6.28319" effort="100" velocity="100"/>
   </joint>
   <joint type="fixed" name="wrist_1_joint_offset">
      <parent link="wrist_1_joint_jointbody"/>
      <child link="wrist_1_link"/>
      <origin xyz="-0.0 -0.0 -0.0" rpy="0.0 0.0 0.0"/>
   </joint>
   <link name="wrist_2_link">
      <inertial>
         <origin xyz="0.0 0.0 0.1" rpy="0.0 0.0 0.0"/>
         <mass value="1.219"/>
         <inertia ixx="0.0025599" iyy="0.0025599" izz="0.0021942" ixy="0" ixz="0" iyz="0"/>
      </inertial>
      <visual name="wrist2_0">
         <origin xyz="-3.800124318643313e-06 0.048536456164498844 0.09943580405134815" rpy="0.17748304010129212 2.000268876756195e-06 1.5707761132131597"/>
         <geometry>
            <mesh filename="meshes/converted_wrist2_0.stl"/>
         </geometry>
         <material name="black"/>
      </visual>
      <visual name="wrist2_1">
         <origin xyz="3.169641991937526e-05 -0.04020605573983935 0.10359119909236272" rpy="0.1111655407064902 0.3094663696047937 1.5711748782855464"/>
         <geometry>
            <mesh filename="meshes/converted_wrist2_1.stl"/>
         </geometry>
         <material name="urblue"/>
      </visual>
      <visual name="wrist2_2">
         <origin xyz="9.000236468802749e-07 0.016056655901336325 0.09663180262077588" rpy="-3.141105944926875 -0.8028358043095716 -1.5708829395525328"/>
         <geometry>
            <mesh filename="meshes/converted_wrist2_2.stl"/>
         </geometry>
         <material name="jointgray"/>
      </visual>
   </link>
   <link name="wrist_2_joint_jointbody">
      <inertial>
         <origin xyz="0.0 0.0 0.0" rpy="0.0 0.0 0.0"/>
         <mass value="0.001"/>
         <inertia ixx="1e-09" iyy="1e-09" izz="1e-09" ixy="0" ixz="0" iyz="0"/>
      </inertial>
   </link>
   <joint type="revolute" name="wrist_2_joint">
      <parent link="wrist_1_link"/>
      <child link="wrist_2_joint_jointbody"/>
      <origin xyz="0.0 0.127 0.0" rpy="0.0 0.0 0.0"/>
      <axis xyz="0.0 0.0 1.0"/>
      <limit lower="-6.28319" upper="6.28319" effort="100" velocity="100"/>
   </joint>
   <joint type="fixed" name="wrist_2_joint_offset">
      <parent link="wrist_2_joint_jointbody"/>
      <child link="wrist_2_link"/>
      <origin xyz="-0.0 -0.0 -0.0" rpy="0.0 0.0 0.0"/>
   </joint>
   <link name="wrist_3_link">
      <inertial>
         <origin xyz="0.0 0.0771683 0.0" rpy="0.0 0.0 1.5707963267948963"/>
         <mass value="0.1889"/>
         <inertia ixx="0.000132134" iyy="9.90863e-05" izz="9.90863e-05" ixy="0" ixz="0" iyz="0"/>
      </inertial>
      <visual name="wrist3">
         <origin xyz="1.3730400112049665e-05 0.07930911085542494 -0.0005378685093544538" rpy="0.22606076193614955 0.004863637864060744 1.5703149455120666"/>
         <geometry>
            <mesh filename="meshes/converted_wrist3.stl"/>
         </geometry>
         <material name="linkgray"/>
      </visual>
   </link>
   <link name="wrist_3_joint_jointbody">
      <inertial>
         <origin xyz="0.0 0.0 0.0" rpy="0.0 0.0 0.0"/>
         <mass value="0.001"/>
         <inertia ixx="1e-09" iyy="1e-09" izz="1e-09" ixy="0" ixz="0" iyz="0"/>
      </inertial>
   </link>
   <joint type="revolute" name="wrist_3_joint">
      <parent link="wrist_2_link"/>
      <child link="wrist_3_joint_jointbody"/>
      <origin xyz="0.0 0.0 0.1" rpy="0.0 0.0 0.0"/>
      <axis xyz="0.0 1.0 0.0"/>
      <limit lower="-6.28319" upper="6.28319" effort="100" velocity="100"/>
   </joint>
   <joint type="fixed" name="wrist_3_joint_offset">
      <parent link="wrist_3_joint_jointbody"/>
      <child link="wrist_3_link"/>
      <origin xyz="-0.0 -0.0 -0.0" rpy="0.0 0.0 0.0"/>
   </joint>
   <link name="base_mount">
      <inertial>
         <origin xyz="-0.0003605835908682333 8.53627523634894e-05 -5.9199370819193636e-05" rpy="0.010714379467335666 -1.5679504402226834 3.132357276590297"/>
         <mass value="0.15000285388020093"/>
         <inertia ixx="0.00010234548781984302" iyy="5.3599686956511186e-05" izz="5.217176229736668e-05" ixy="0" ixz="0" iyz="0"/>
      </inertial>
      <visual name="base_mount">
         <origin xyz="-0.0003605835908682333 8.53627523634894e-05 -5.919937081919364e-05" rpy="0.01071452283964236 -1.5679504779870121 3.1323571332523317"/>
         <geometry>
            <mesh filename="meshes/converted_base_mount.stl"/>
         </geometry>
         <material name="gripper_black"/>
      </visual>
   </link>
   <link name="wrist_3_link2base_mount_fixed_jointbody">
      <inertial>
         <origin xyz="0.0 0.0 0.0" rpy="0.0 0.0 0.0"/>
         <mass value="0.001"/>
         <inertia ixx="1e-09" iyy="1e-09" izz="1e-09" ixy="0" ixz="0" iyz="0"/>
      </inertial>
   </link>
   <joint type="fixed" name="wrist_3_link2base_mount_fixed">
      <parent link="wrist_3_link"/>
      <child link="wrist_3_link2base_mount_fixed_jointbody"/>
      <origin xyz="0.0 0.1 0.0" rpy="-1.5707963267948957 0.0 0.0"/>
   </joint>
   <joint type="fixed" name="wrist_3_link2base_mount_fixed_offset">
      <parent link="wrist_3_link2base_mount_fixed_jointbody"/>
      <child link="base_mount"/>
      <origin xyz="-0.0 -0.0 -0.0" rpy="0.0 0.0 0.0"/>
   </joint>
   <link name="gripper_base">
      <inertial>
         <origin xyz="0.0 -2.70394e-05 0.0354675" rpy="-0.0030569776193478805 0.0 0.0"/>
         <mass value="0.777441"/>
         <inertia ixx="0.000260285" iyy="0.000225381" izz="0.000152708" ixy="0" ixz="0" iyz="0"/>
      </inertial>
      <visual name="gripper_base">
         <origin xyz="9.197026165775215e-08 -2.7039392101011293e-05 0.0354674813211748" rpy="-0.003056990542377661 7.761755149715555e-08 2.539010455466519e-05"/>
         <geometry>
            <mesh filename="meshes/converted_gripper_base.stl"/>
         </geometry>
         <material name="gripper_black"/>
      </visual>
   </link>
   <link name="base_mount2gripper_base_fixed_jointbody">
      <inertial>
         <origin xyz="0.0 0.0 0.0" rpy="0.0 0.0 0.0"/>
         <mass value="0.001"/>
         <inertia ixx="1e-09" iyy="1e-09" izz="1e-09" ixy="0" ixz="0" iyz="0"/>
      </inertial>
   </link>
   <joint type="fixed" name="base_mount2gripper_base_fixed">
      <parent link="base_mount"/>
      <child link="base_mount2gripper_base_fixed_jointbody"/>
      <origin xyz="0.0 0.0 0.0038" rpy="0.0 0.0 -1.5707963267948957"/>
   </joint>
   <joint type="fixed" name="base_mount2gripper_base_fixed_offset">
      <parent link="base_mount2gripper_base_fixed_jointbody"/>
      <child link="gripper_base"/>
      <origin xyz="-0.0 -0.0 -0.0" rpy="0.0 0.0 0.0"/>
   </joint>
   <link name="right_driver">
      <inertial>
         <origin xyz="2.96931e-12 0.0177547 0.00107314" rpy="1.6425151722801996 0.0 0.0"/>
         <mass value="0.00899563"/>
         <inertia ixx="1.72352e-06" iyy="1.60906e-06" izz="3.22006e-07" ixy="0" ixz="0" iyz="0"/>
      </inertial>
      <visual name="driver">
         <origin xyz="2.9693095360038857e-12 0.017754693326339378 0.001073141648831213" rpy="1.642515910368616 0.0 0.0"/>
         <geometry>
            <mesh filename="meshes/converted_driver.stl"/>
         </geometry>
         <material name="gray"/>
      </visual>
   </link>
   <link name="right_driver_joint_jointbody">
      <inertial>
         <origin xyz="0.0 0.0 0.0" rpy="0.0 0.0 0.0"/>
         <mass value="0.001"/>
         <inertia ixx="1e-09" iyy="1e-09" izz="1e-09" ixy="0" ixz="0" iyz="0"/>
      </inertial>
   </link>
   <joint type="revolute" name="right_driver_joint">
      <parent link="gripper_base"/>
      <child link="right_driver_joint_jointbody"/>
      <origin xyz="0.0 0.0306011 0.054904" rpy="0.0 0.0 0.0"/>
      <axis xyz="1.0 0.0 0.0"/>
      <limit lower="0.0" upper="0.8" effort="100" velocity="100"/>
   </joint>
   <joint type="fixed" name="right_driver_joint_offset">
      <parent link="right_driver_joint_jointbody"/>
      <child link="right_driver"/>
      <origin xyz="-0.0 -0.0 -0.0" rpy="0.0 0.0 0.0"/>
   </joint>
   <link name="right_coupler">
      <inertial>
         <origin xyz="0.0 0.00301209 0.0232175" rpy="0.0 0.12903854724165864 1.5707963267948966"/>
         <mass value="0.0140974"/>
         <inertia ixx="4.16206e-06" iyy="3.52216e-06" izz="8.88131e-07" ixy="0" ixz="0" iyz="0"/>
      </inertial>
      <visual name="coupler">
         <origin xyz="8.458042296975096e-13 0.003012085414741031 0.023217538318615817" rpy="0.0 0.12903875752327765 1.5707963267948966"/>
         <geometry>
            <mesh filename="meshes/converted_coupler.stl"/>
         </geometry>
         <material name="gripper_black"/>
      </visual>
   </link>
   <link name="right_coupler_joint_jointbody">
      <inertial>
         <origin xyz="0.0 0.0 0.0" rpy="0.0 0.0 0.0"/>
         <mass value="0.001"/>
         <inertia ixx="1e-09" iyy="1e-09" izz="1e-09" ixy="0" ixz="0" iyz="0"/>
      </inertial>
   </link>
   <joint type="revolute" name="right_coupler_joint">
      <parent link="right_driver"/>
      <child link="right_coupler_joint_jointbody"/>
      <origin xyz="0.0 0.0315 -0.0041" rpy="0.0 0.0 0.0"/>
      <axis xyz="1.0 0.0 0.0"/>
      <limit lower="-1.57" upper="0.0" effort="100" velocity="100"/>
   </joint>
   <joint type="fixed" name="right_coupler_joint_offset">
      <parent link="right_coupler_joint_jointbody"/>
      <child link="right_coupler"/>
      <origin xyz="-0.0 -0.0 -0.0" rpy="0.0 0.0 0.0"/>
   </joint>
   <link name="right_spring_link">
      <inertial>
         <origin xyz="-8.65005e-09 0.0181624 0.0212658" rpy="0.0 0.7068443151232264 1.5707963267948966"/>
         <mass value="0.0221642"/>
         <inertia ixx="8.96853e-06" iyy="6.71733e-06" izz="2.63931e-06" ixy="0" ixz="0" iyz="0"/>
      </inertial>
      <visual name="spring_link">
         <origin xyz="-8.650050113628342e-09 0.018162399838260603 0.021265809871824037" rpy="0.0 0.7068435008139309 1.5707963267948966"/>
         <geometry>
            <mesh filename="meshes/converted_spring_link.stl"/>
         </geometry>
         <material name="gripper_black"/>
      </visual>
   </link>
   <link name="right_spring_link_joint_jointbody">
      <inertial>
         <origin xyz="0.0 0.0 0.0" rpy="0.0 0.0 0.0"/>
         <mass value="0.001"/>
         <inertia ixx="1e-09" iyy="1e-09" izz="1e-09" ixy="0" ixz="0" iyz="0"/>
      </inertial>
   </link>
   <joint type="revolute" name="right_spring_link_joint">
      <parent link="gripper_base"/>
      <child link="right_spring_link_joint_jointbody"/>
      <origin xyz="0.0 0.0132 0.0609" rpy="0.0 0.0 0.0"/>
      <axis xyz="1.0 0.0 0.0"/>
      <limit lower="-0.29670597283" upper="0.8" effort="100" velocity="100"/>
   </joint>
   <joint type="fixed" name="right_spring_link_joint_offset">
      <parent link="right_spring_link_joint_jointbody"/>
      <child link="right_spring_link"/>
      <origin xyz="-0.0 -0.0 -0.0" rpy="0.0 0.0 0.0"/>
   </joint>
   <link name="right_follower">
      <inertial>
         <origin xyz="0.0 -0.011046 0.0124786" rpy="0.32977841348127324 0.0 0.0"/>
         <mass value="0.0125222"/>
         <inertia ixx="2.67415e-06" iyy="2.4559e-06" izz="6.02031e-07" ixy="0" ixz="0" iyz="0"/>
      </inertial>
      <visual name="follower">
         <origin xyz="-8.222505669797204e-08 -0.011045964820441189 0.012478641054290796" rpy="0.3343560463823991 1.1571605218252401e-05 4.019967359436549e-06"/>
         <geometry>
            <mesh filename="meshes/converted_follower.stl"/>
         </geometry>
         <material name="gripper_black"/>
      </visual>
   </link>
   <link name="right_follower_joint_jointbody">
      <inertial>
         <origin xyz="0.0 0.0 0.0" rpy="0.0 0.0 0.0"/>
         <mass value="0.001"/>
         <inertia ixx="1e-09" iyy="1e-09" izz="1e-09" ixy="0" ixz="0" iyz="0"/>
      </inertial>
   </link>
   <joint type="revolute" name="right_follower_joint">
      <parent link="right_spring_link"/>
      <child link="right_follower_joint_jointbody"/>
      <origin xyz="0.0 0.037000000000000005 0.044" rpy="0.0 0.0 0.0"/>
      <axis xyz="1.0 0.0 0.0"/>
      <limit lower="-0.872664" upper="0.872664" effort="100" velocity="100"/>
   </joint>
   <joint type="fixed" name="right_follower_joint_offset">
      <parent link="right_follower_joint_jointbody"/>
      <child link="right_follower"/>
      <origin xyz="-0.0 0.018 -0.0065" rpy="0.0 0.0 0.0"/>
   </joint>
   <link name="right_pad">
      <inertial>
         <origin xyz="0.0 -0.0025 0.0185" rpy="0.0 0.0 1.5707963267948963"/>
         <mass value="0.0035"/>
         <inertia ixx="4.73958e-07" iyy="3.64583e-07" izz="1.23958e-07" ixy="0" ixz="0" iyz="0"/>
      </inertial>
      <visual name="pad">
         <origin xyz="1.9278732063789526e-14 -0.0024999999150168138 0.018517375704529604" rpy="0.0 0.0 1.5707963267948966"/>
         <geometry>
            <mesh filename="meshes/converted_pad.stl"/>
         </geometry>
         <material name="gripper_black"/>
      </visual>
   </link>
   <link name="right_follower2right_pad_fixed_jointbody">
      <inertial>
         <origin xyz="0.0 0.0 0.0" rpy="0.0 0.0 0.0"/>
         <mass value="0.001"/>
         <inertia ixx="1e-09" iyy="1e-09" izz="1e-09" ixy="0" ixz="0" iyz="0"/>
      </inertial>
   </link>
   <joint type="fixed" name="right_follower2right_pad_fixed">
      <parent link="right_follower"/>
      <child link="right_follower2right_pad_fixed_jointbody"/>
      <origin xyz="0.0 -0.0189 0.01352" rpy="0.0 0.0 0.0"/>
   </joint>
   <joint type="fixed" name="right_follower2right_pad_fixed_offset">
      <parent link="right_follower2right_pad_fixed_jointbody"/>
      <child link="right_pad"/>
      <origin xyz="-0.0 -0.0 -0.0" rpy="0.0 0.0 0.0"/>
   </joint>
   <link name="right_silicone_pad">
      <inertial>
         <origin xyz="1.9279010081721142e-14 -0.005799999926239252 0.018517375704574398" rpy="0.0 0.0 1.5707963267948963"/>
         <mass value="0.0013028120143261008"/>
         <inertia ixx="2.0080436065436886e-07" iyy="1.4953603981518107e-07" izz="5.1824187343216365e-08" ixy="0" ixz="0" iyz="0"/>
      </inertial>
      <visual name="silicone_pad">
         <origin xyz="1.9279010081721142e-14 -0.005799999926239252 0.018517375704574398" rpy="0.0 0.0 1.5707963267948966"/>
         <geometry>
            <mesh filename="meshes/converted_silicone_pad.stl"/>
         </geometry>
         <material name="gripper_black"/>
      </visual>
   </link>
   <link name="right_pad2right_silicone_pad_fixed_jointbody">
      <inertial>
         <origin xyz="0.0 0.0 0.0" rpy="0.0 0.0 0.0"/>
         <mass value="0.001"/>
         <inertia ixx="1e-09" iyy="1e-09" izz="1e-09" ixy="0" ixz="0" iyz="0"/>
      </inertial>
   </link>
   <joint type="fixed" name="right_pad2right_silicone_pad_fixed">
      <parent link="right_pad"/>
      <child link="right_pad2right_silicone_pad_fixed_jointbody"/>
      <origin xyz="0.0 0.0 0.0" rpy="0.0 0.0 0.0"/>
   </joint>
   <joint type="fixed" name="right_pad2right_silicone_pad_fixed_offset">
      <parent link="right_pad2right_silicone_pad_fixed_jointbody"/>
      <child link="right_silicone_pad"/>
      <origin xyz="-0.0 -0.0 -0.0" rpy="0.0 0.0 0.0"/>
   </joint>
   <link name="left_driver">
      <inertial>
         <origin xyz="0.0 0.0177547 0.00107314" rpy="1.6425151722801996 0.0 0.0"/>
         <mass value="0.00899563"/>
         <inertia ixx="1.72352e-06" iyy="1.60906e-06" izz="3.22006e-07" ixy="0" ixz="0" iyz="0"/>
      </inertial>
      <visual name="driver">
         <origin xyz="2.9693095360038857e-12 0.017754693326339378 0.001073141648831213" rpy="1.642515910368616 0.0 0.0"/>
         <geometry>
            <mesh filename="meshes/converted_driver.stl"/>
         </geometry>
         <material name="gray"/>
      </visual>
   </link>
   <link name="left_driver_joint_jointbody">
      <inertial>
         <origin xyz="0.0 0.0 0.0" rpy="0.0 0.0 0.0"/>
         <mass value="0.001"/>
         <inertia ixx="1e-09" iyy="1e-09" izz="1e-09" ixy="0" ixz="0" iyz="0"/>
      </inertial>
   </link>
   <joint type="revolute" name="left_driver_joint">
      <parent link="gripper_base"/>
      <child link="left_driver_joint_jointbody"/>
      <origin xyz="0.0 -0.0306011 0.054904" rpy="0.0 0.0 3.141592653589793"/>
      <axis xyz="1.0 0.0 0.0"/>
      <limit lower="0.0" upper="0.8" effort="100" velocity="100"/>
   </joint>
   <joint type="fixed" name="left_driver_joint_offset">
      <parent link="left_driver_joint_jointbody"/>
      <child link="left_driver"/>
      <origin xyz="-0.0 -0.0 -0.0" rpy="0.0 0.0 0.0"/>
   </joint>
   <link name="left_coupler">
      <inertial>
         <origin xyz="0.0 0.00301209 0.0232175" rpy="0.0 0.12903854724165864 1.5707963267948966"/>
         <mass value="0.0140974"/>
         <inertia ixx="4.16206e-06" iyy="3.52216e-06" izz="8.88131e-07" ixy="0" ixz="0" iyz="0"/>
      </inertial>
      <visual name="coupler">
         <origin xyz="8.458042296975096e-13 0.003012085414741031 0.023217538318615817" rpy="0.0 0.12903875752327765 1.5707963267948966"/>
         <geometry>
            <mesh filename="meshes/converted_coupler.stl"/>
         </geometry>
         <material name="gripper_black"/>
      </visual>
   </link>
   <link name="left_coupler_joint_jointbody">
      <inertial>
         <origin xyz="0.0 0.0 0.0" rpy="0.0 0.0 0.0"/>
         <mass value="0.001"/>
         <inertia ixx="1e-09" iyy="1e-09" izz="1e-09" ixy="0" ixz="0" iyz="0"/>
      </inertial>
   </link>
   <joint type="revolute" name="left_coupler_joint">
      <parent link="left_driver"/>
      <child link="left_coupler_joint_jointbody"/>
      <origin xyz="0.0 0.0315 -0.0041" rpy="0.0 0.0 0.0"/>
      <axis xyz="1.0 0.0 0.0"/>
      <limit lower="-1.57" upper="0.0" effort="100" velocity="100"/>
   </joint>
   <joint type="fixed" name="left_coupler_joint_offset">
      <parent link="left_coupler_joint_jointbody"/>
      <child link="left_coupler"/>
      <origin xyz="-0.0 -0.0 -0.0" rpy="0.0 0.0 0.0"/>
   </joint>
   <link name="left_spring_link">
      <inertial>
         <origin xyz="-8.65005e-09 0.0181624 0.0212658" rpy="0.0 0.7068443151232264 1.5707963267948966"/>
         <mass value="0.0221642"/>
         <inertia ixx="8.96853e-06" iyy="6.71733e-06" izz="2.63931e-06" ixy="0" ixz="0" iyz="0"/>
      </inertial>
      <visual name="spring_link">
         <origin xyz="-8.650050113628342e-09 0.018162399838260603 0.021265809871824037" rpy="0.0 0.7068435008139309 1.5707963267948966"/>
         <geometry>
            <mesh filename="meshes/converted_spring_link.stl"/>
         </geometry>
         <material name="gripper_black"/>
      </visual>
   </link>
   <link name="left_spring_link_joint_jointbody">
      <inertial>
         <origin xyz="0.0 0.0 0.0" rpy="0.0 0.0 0.0"/>
         <mass value="0.001"/>
         <inertia ixx="1e-09" iyy="1e-09" izz="1e-09" ixy="0" ixz="0" iyz="0"/>
      </inertial>
   </link>
   <joint type="revolute" name="left_spring_link_joint">
      <parent link="gripper_base"/>
      <child link="left_spring_link_joint_jointbody"/>
      <origin xyz="0.0 -0.0132 0.0609" rpy="0.0 0.0 3.141592653589793"/>
      <axis xyz="1.0 0.0 0.0"/>
      <limit lower="-0.29670597283" upper="0.8" effort="100" velocity="100"/>
   </joint>
   <joint type="fixed" name="left_spring_link_joint_offset">
      <parent link="left_spring_link_joint_jointbody"/>
      <child link="left_spring_link"/>
      <origin xyz="-0.0 -0.0 -0.0" rpy="0.0 0.0 0.0"/>
   </joint>
   <link name="left_follower">
      <inertial>
         <origin xyz="0.0 -0.011046 0.0124786" rpy="0.32977841348127324 0.0 0.0"/>
         <mass value="0.0125222"/>
         <inertia ixx="2.67415e-06" iyy="2.4559e-06" izz="6.02031e-07" ixy="0" ixz="0" iyz="0"/>
      </inertial>
      <visual name="follower">
         <origin xyz="-8.222505669797204e-08 -0.011045964820441189 0.012478641054290796" rpy="0.3343560463823991 1.1571605218252401e-05 4.019967359436549e-06"/>
         <geometry>
            <mesh filename="meshes/converted_follower.stl"/>
         </geometry>
         <material name="gripper_black"/>
      </visual>
   </link>
   <link name="left_follower_joint_jointbody">
      <inertial>
         <origin xyz="0.0 0.0 0.0" rpy="0.0 0.0 0.0"/>
         <mass value="0.001"/>
         <inertia ixx="1e-09" iyy="1e-09" izz="1e-09" ixy="0" ixz="0" iyz="0"/>
      </inertial>
   </link>
   <joint type="revolute" name="left_follower_joint">
      <parent link="left_spring_link"/>
      <child link="left_follower_joint_jointbody"/>
      <origin xyz="0.0 0.037000000000000005 0.044" rpy="0.0 0.0 0.0"/>
      <axis xyz="1.0 0.0 0.0"/>
      <limit lower="-0.872664" upper="0.872664" effort="100" velocity="100"/>
   </joint>
   <joint type="fixed" name="left_follower_joint_offset">
      <parent link="left_follower_joint_jointbody"/>
      <child link="left_follower"/>
      <origin xyz="-0.0 0.018 -0.0065" rpy="0.0 0.0 0.0"/>
   </joint>
   <link name="left_pad">
      <inertial>
         <origin xyz="0.0 -0.0025 0.0185" rpy="0.0 0.0 1.5707963267948963"/>
         <mass value="0.0035"/>
         <inertia ixx="4.73958e-07" iyy="3.64583e-07" izz="1.23958e-07" ixy="0" ixz="0" iyz="0"/>
      </inertial>
      <visual name="pad">
         <origin xyz="1.9278732063789526e-14 -0.0024999999150168138 0.018517375704529604" rpy="0.0 0.0 1.5707963267948966"/>
         <geometry>
            <mesh filename="meshes/converted_pad.stl"/>
         </geometry>
         <material name="gripper_black"/>
      </visual>
   </link>
   <link name="left_follower2left_pad_fixed_jointbody">
      <inertial>
         <origin xyz="0.0 0.0 0.0" rpy="0.0 0.0 0.0"/>
         <mass value="0.001"/>
         <inertia ixx="1e-09" iyy="1e-09" izz="1e-09" ixy="0" ixz="0" iyz="0"/>
      </inertial>
   </link>
   <joint type="fixed" name="left_follower2left_pad_fixed">
      <parent link="left_follower"/>
      <child link="left_follower2left_pad_fixed_jointbody"/>
      <origin xyz="0.0 -0.0189 0.01352" rpy="0.0 0.0 0.0"/>
   </joint>
   <joint type="fixed" name="left_follower2left_pad_fixed_offset">
      <parent link="left_follower2left_pad_fixed_jointbody"/>
      <child link="left_pad"/>
      <origin xyz="-0.0 -0.0 -0.0" rpy="0.0 0.0 0.0"/>
   </joint>
   <link name="left_silicone_pad">
      <inertial>
         <origin xyz="1.9279010081721142e-14 -0.005799999926239252 0.018517375704574398" rpy="0.0 0.0 1.5707963267948963"/>
         <mass value="0.0013028120143261008"/>
         <inertia ixx="2.0080436065436886e-07" iyy="1.4953603981518107e-07" izz="5.1824187343216365e-08" ixy="0" ixz="0" iyz="0"/>
      </inertial>
      <visual name="silicone_pad">
         <origin xyz="1.9279010081721142e-14 -0.005799999926239252 0.018517375704574398" rpy="0.0 0.0 1.5707963267948966"/>
         <geometry>
            <mesh filename="meshes/converted_silicone_pad.stl"/>
         </geometry>
         <material name="gripper_black"/>
      </visual>
   </link>
   <link name="left_pad2left_silicone_pad_fixed_jointbody">
      <inertial>
         <origin xyz="0.0 0.0 0.0" rpy="0.0 0.0 0.0"/>
         <mass value="0.001"/>
         <inertia ixx="1e-09" iyy="1e-09" izz="1e-09" ixy="0" ixz="0" iyz="0"/>
      </inertial>
   </link>
   <joint type="fixed" name="left_pad2left_silicone_pad_fixed">
      <parent link="left_pad"/>
      <child link="left_pad2left_silicone_pad_fixed_jointbody"/>
      <origin xyz="0.0 0.0 0.0" rpy="0.0 0.0 0.0"/>
   </joint>
   <joint type="fixed" name="left_pad2left_silicone_pad_fixed_offset">
      <parent link="left_pad2left_silicone_pad_fixed_jointbody"/>
      <child link="left_silicone_pad"/>
      <origin xyz="-0.0 -0.0 -0.0" rpy="0.0 0.0 0.0"/>
   </joint>
   <link name="d435i">
      <inertial>
         <origin xyz="0.0014511348017872574 -0.0003193267750761583 -0.01354119004097661" rpy="1.6323782071719153 -1.4906062228156745 1.5071320126951782"/>
         <mass value="0.072"/>
         <inertia ixx="3.799399738297598e-05" iyy="3.70549969728162e-05" izz="4.554668915769219e-06" ixy="0" ixz="0" iyz="0"/>
      </inertial>
      <visual name="d435i_0">
         <origin xyz="-0.007502287323788545 3.0005508763874497e-07 -0.0013673948796411991" rpy="3.141592653589793 -1.5707963267948966 0.0"/>
         <geometry>
            <mesh filename="meshes/converted_d435i_0.stl"/>
         </geometry>
         <material name="IR_Lens"/>
      </visual>
      <visual name="d435i_1">
         <origin xyz="-0.011499967618063702 -2.5466330329643412e-08 -0.003978610932321857" rpy="1.5707963267948966 -1.5707963267948966 0.0"/>
         <geometry>
            <mesh filename="meshes/converted_d435i_1.stl"/>
         </geometry>
         <material name="IR_Emitter_Lens"/>
      </visual>
      <visual name="d435i_2">
         <origin xyz="-0.006740902082927329 9.621788091553945e-05 -0.002869882318486055" rpy="1.5909447520597275 -1.3518688989480427 1.5615809337103432"/>
         <geometry>
            <mesh filename="meshes/converted_d435i_2.stl"/>
         </geometry>
         <material name="IR_Rim"/>
      </visual>
      <visual name="d435i_3">
         <origin xyz="-0.007508819633473903 -1.048028024602221e-06 -0.0011700158943132035" rpy="3.141592653589793 -1.5707963267948966 0.0"/>
         <geometry>
            <mesh filename="meshes/converted_d435i_3.stl"/>
         </geometry>
         <material name="IR_Lens"/>
      </visual>
      <visual name="d435i_4">
         <origin xyz="-0.005241830708849777 0.0002548412830941167 -0.007093877744591685" rpy="0.08323071530627812 -1.5455844769762819 3.069567742664027"/>
         <geometry>
            <mesh filename="meshes/converted_d435i_4.stl"/>
         </geometry>
         <material name="Cameras_Gray"/>
      </visual>
      <visual name="d435i_5">
         <origin xyz="-0.0028610612363454426 -8.261777537953463e-05 -0.0016461957198015743" rpy="-1.3473582254981396 -1.5641950357529448 -1.7931440866286792"/>
         <geometry>
            <mesh filename="meshes/converted_d435i_5.stl"/>
         </geometry>
         <material name="Black_Acrylic"/>
      </visual>
      <visual name="d435i_6">
         <origin xyz="0.03249426520107115 4.7493657758214e-06 -0.0051918172363593015" rpy="3.1302011949776776 -1.5707963267948966 0.0"/>
         <geometry>
            <mesh filename="meshes/converted_d435i_6.stl"/>
         </geometry>
         <material name="Black_Acrylic"/>
      </visual>
      <visual name="d435i_7">
         <origin xyz="0.032499927055554816 6.196556999013861e-07 -0.0036345687064755767" rpy="0.0 0.0 0.0"/>
         <geometry>
            <mesh filename="meshes/converted_d435i_7.stl"/>
         </geometry>
         <material name="RGB_Pupil"/>
      </visual>
      <visual name="d435i_8">
         <origin xyz="0.0014511348017872574 -0.0003193267750761583 -0.01354119004097661" rpy="1.6323782072389574 -1.4906062228061316 1.507132012701543"/>
         <geometry>
            <mesh filename="meshes/converted_d435i_8.stl"/>
         </geometry>
         <material name="Metal_Casing"/>
      </visual>
   </link>
   <link name="wrist_3_link2d435i_fixed_jointbody">
      <inertial>
         <origin xyz="0.0 0.0 0.0" rpy="0.0 0.0 0.0"/>
         <mass value="0.001"/>
         <inertia ixx="1e-09" iyy="1e-09" izz="1e-09" ixy="0" ixz="0" iyz="0"/>
      </inertial>
   </link>
   <joint type="fixed" name="wrist_3_link2d435i_fixed">
      <parent link="wrist_3_link"/>
      <child link="wrist_3_link2d435i_fixed_jointbody"/>
      <origin xyz="0.0 0.1 -0.05" rpy="-1.5708000000000002 0.0 0.0"/>
   </joint>
   <joint type="fixed" name="wrist_3_link2d435i_fixed_offset">
      <parent link="wrist_3_link2d435i_fixed_jointbody"/>
      <child link="d435i"/>
      <origin xyz="-0.0 -0.0 -0.0" rpy="0.0 0.0 0.0"/>
   </joint>
   <link name="camera_frame">
      <inertial>
         <origin xyz="0.0 0.0 0.0" rpy="0.0 0.0 0.0"/>
         <mass value="0.0"/>
         <inertia ixx="0.0" iyy="0.0" izz="0.0" ixy="0" ixz="0" iyz="0"/>
      </inertial>
   </link>
   <link name="d435i2camera_frame_fixed_jointbody">
      <inertial>
         <origin xyz="0.0 0.0 0.0" rpy="0.0 0.0 0.0"/>
         <mass value="0.001"/>
         <inertia ixx="1e-09" iyy="1e-09" izz="1e-09" ixy="0" ixz="0" iyz="0"/>
      </inertial>
   </link>
   <joint type="fixed" name="d435i2camera_frame_fixed">
      <parent link="d435i"/>
      <child link="d435i2camera_frame_fixed_jointbody"/>
      <origin xyz="0.0 0.0 0.0" rpy="0.0 0.0 0.0"/>
   </joint>
   <joint type="fixed" name="d435i2camera_frame_fixed_offset">
      <parent link="d435i2camera_frame_fixed_jointbody"/>
      <child link="camera_frame"/>
      <origin xyz="-0.0 -0.0 -0.0" rpy="0.0 0.0 0.0"/>
   </joint>
   <material name="black">
     <color rgba="0.033 0.033 0.033 1"/>
   </material>
   <material name="jointgray">
     <color rgba="0.278 0.278 0.278 1"/>
   </material>
   <material name="linkgray">
     <color rgba="0.82 0.82 0.82 1"/>
   </material>
   <material name="urblue">
     <color rgba="0.49 0.678 0.8 1"/>
   </material>
   <material name="metal">
     <color rgba="0.58 0.58 0.58 1"/>
   </material>
   <material name="silicone">
     <color rgba="0.1882 0.1882 0.1882 1"/>
   </material>
   <material name="gray">
     <color rgba="0.4627 0.4627 0.4627 1"/>
   </material>
   <material name="gripper_black">
     <color rgba="0.149 0.149 0.149 1"/>
   </material>
   <material name="Black_Acrylic">
     <color rgba="0.070360 0.070360 0.070360 1"/>
   </material>
   <material name="Cameras_Gray">
     <color rgba="0.296138 0.296138 0.296138 1"/>
   </material>
   <material name="IR_Emitter_Lens">
     <color rgba="0.287440 0.665387 0.327778 1"/>
   </material>
   <material name="IR_Lens">
     <color rgba="0.035601 0.035601 0.035601 1"/>
   </material>
   <material name="IR_Rim">
     <color rgba="0.799102 0.806952 0.799103 1"/>
   </material>
   <material name="Metal_Casing">
     <color rgba="1 1 1 1"/>
   </material>
   <material name="RGB_Pupil">
     <color rgba="0.087140 0.002866 0.009346 1"/>
   </material>
</robot>
